Workbook

Sheet Asignaciones
A1: Id Local* | B1: Id Elemento* | C1: Nombre Local | D1: Nombre Elemento
A2: 100 | B2: 567 | C2: =IFERROR(_xlfn.XLOOKUP(VALUE(A2),Locales!$A$2:$A$723,Locales!$B$2:$B$723),"No encontrado") -> 8633992 FLAVIO RICARDO SOBARZO FRIZ-SUPER 8_FLAVIO RICARDO SOBARZO FRIZ_ PARRAL | D2: =IFERROR(_xlfn.XLOOKUP(VALUE(B2),Elementos!$A$2:$A$808,Elementos!$B$2:$B$808),"No encontrado") -> JUREL MED NAT SJ 24X425 (240)
A3: 100 | B3: 787 | C3: =IFERROR(_xlfn.XLOOKUP(VALUE(A3),Locales!$A$2:$A$723,Locales!$B$2:$B$723),"No encontrado") -> 8633992 FLAVIO RICARDO SOBARZO FRIZ-SUPER 8_FLAVIO RICARDO SOBARZO FRIZ_ PARRAL | D3: =IFERROR(_xlfn.XLOOKUP(VALUE(B3),Elementos!$A$2:$A$808,Elementos!$B$2:$B$808),"No encontrado") -> JUREL LOMO NAT SJ 48X160GR
A4: 100 | B4: 788 | C4: =IFERROR(_xlfn.XLOOKUP(VALUE(A4),Locales!$A$2:$A$723,Locales!$B$2:$B$723),"No encontrado") -> 8633992 FLAVIO RICARDO SOBARZO FRIZ-SUPER 8_FLAVIO RICARDO SOBARZO FRIZ_ PARRAL | D4: =IFERROR(_xlfn.XLOOKUP(VALUE(B4),Elementos!$A$2:$A$808,Elementos!$B$2:$B$808),"No encontrado") -> JUREL LOMO ACTE SJ 48X160GR
A5: 100 | B5: 789 | C5: =IFERROR(_xlfn.XLOOKUP(VALUE(A5),Locales!$A$2:$A$723,Locales!$B$2:$B$723),"No encontrado") -> 8633992 FLAVIO RICARDO SOBARZO FRIZ-SUPER 8_FLAVIO RICARDO SOBARZO FRIZ_ PARRAL | D5: =IFERROR(_xlfn.XLOOKUP(VALUE(B5),Elementos!$A$2:$A$808,Elementos!$B$2:$B$808),"No encontrado") -> JUREL LOMO AHUMADO SJ 48X160GR
A6: 100 | B6: 775 | C6: =IFERROR(_xlfn.XLOOKUP(VALUE(A6),Locales!$A$2:$A$723,Locales!$B$2:$B$723),"No encontrado") -> 8633992 FLAVIO RICARDO SOBARZO FRIZ-SUPER 8_FLAVIO RICARDO SOBARZO FRIZ_ PARRAL | D6: =IFERROR(_xlfn.XLOOKUP(VALUE(B6),Elementos!$A$2:$A$808,Elementos!$B$2:$B$808),"No encontrado") -> CHORITO ENTERO NAT SJ 48X190
A7: 100 | B7: 776 | C7: =IFERROR(_xlfn.XLOOKUP(VALUE(A7),Locales!$A$2:$A$723,Locales!$B$2:$B$723),"No encontrado") -> 8633992 FLAVIO RICARDO SOBARZO FRIZ-SUPER 8_FLAVIO RICARDO SOBARZO FRIZ_ PARRAL | D7: =IFERROR(_xlfn.XLOOKUP(VALUE(B7),Elementos!$A$2:$A$808,Elementos!$B$2:$B$808),"No encontrado") -> CHORITO ENTERO ACTE SJ 48X190
A8: 100 | B8: 780 | C8: =IFERROR(_xlfn.XLOOKUP(VALUE(A8),Locales!$A$2:$A$723,Locales!$B$2:$B$723),"No encontrado") -> 8633992 FLAVIO RICARDO SOBARZO FRIZ-SUPER 8_FLAVIO RICARDO SOBARZO FRIZ_ PARRAL | D8: =IFERROR(_xlfn.XLOOKUP(VALUE(B8),Elementos!$A$2:$A$808,Elementos!$B$2:$B$808),"No encontrado") -> CHORITO ENTERO BAJOSOD SJ 48X190
A9: 100 | B9: 777 | C9: =IFERROR(_xlfn.XLOOKUP(VALUE(A9),Locales!$A$2:$A$723,Locales!$B$2:$B$723),"No encontrado") -> 8633992 FLAVIO RICARDO SOBARZO FRIZ-SUPER 8_FLAVIO RICARDO SOBARZO FRIZ_ PARRAL | D9: =IFERROR(_xlfn.XLOOKUP(VALUE(B9),Elementos!$A$2:$A$808,Elementos!$B$2:$B$808),"No encontrado") -> CHORITO ENTERO NAT SJ 24X425
A10: 100 | B10: 778 | C10: =IFERROR(_xlfn.XLOOKUP(VALUE(A10),Locales!$A$2:$A$723,Locales!$B$2:$B$723),"No encontrado") -> 8633992 FLAVIO RICARDO SOBARZO FRIZ-SUPER 8_FLAVIO RICARDO SOBARZO FRIZ_ PARRAL | D10: =IFERROR(_xlfn.XLOOKUP(VALUE(B10),Elementos!$A$2:$A$808,Elementos!$B$2:$B$808),"No encontrado") -> CHORITO ENTERO ACTE SJ 24X425
A11: 100 | B11: 404 | C11: =IFERROR(_xlfn.XLOOKUP(VALUE(A11),Locales!$A$2:$A$723,Locales!$B$2:$B$723),"No encontrado") -> 8633992 FLAVIO RICARDO SOBARZO FRIZ-SUPER 8_FLAVIO RICARDO SOBARZO FRIZ_ PARRAL | D11: =IFERROR(_xlfn.XLOOKUP(VALUE(B11),Elementos!$A$2:$A$808,Elementos!$B$2:$B$808),"No encontrado") -> CHOLGAS EN ACEITE SAN JOSE 100 GR DR
A12: 100 | B12: 405 | C12: =IFERROR(_xlfn.XLOOKUP(VALUE(A12),Locales!$A$2:$A$723,Locales!$B$2:$B$723),"No encontrado") -> 8633992 FLAVIO RICARDO SOBARZO FRIZ-SUPER 8_FLAVIO RICARDO SOBARZO FRIZ_ PARRAL | D12: =IFERROR(_xlfn.XLOOKUP(VALUE(B12),Elementos!$A$2:$A$808,Elementos!$B$2:$B$808),"No encontrado") -> CHOLGAS NATURAL SAN JOSE 110 GR DR
A13: 100 | B13: 662 | C13: =IFERROR(_xlfn.XLOOKUP(VALUE(A13),Locales!$A$2:$A$723,Locales!$B$2:$B$723),"No encontrado") -> 8633992 FLAVIO RICARDO SOBARZO FRIZ-SUPER 8_FLAVIO RICARDO SOBARZO FRIZ_ PARRAL | D13: =IFERROR(_xlfn.XLOOKUP(VALUE(B13),Elementos!$A$2:$A$808,Elementos!$B$2:$B$808),"No encontrado") -> MARISCOS SURT NAT SJ ML X48
... A6780: 96 | B6780: 791 | C6780: =IFERROR(_xlfn.XLOOKUP(VALUE(A6780),Locales!$A$2:$A$723,Locales!$B$2:$B$723),"No encontrado") -> 76727062 LA GANGA LINARES-LA GANGA _JANUARIO ESPINOZA 848 - LINARES | D6780: =IFERROR(_xlfn.XLOOKUP(VALUE(B6780),Elementos!$A$2:$A$808,Elementos!$B$2:$B$808),"No encontrado") -> ATUN LOM NAT SJ 48X140

Sheet Locales
A1: Id Local | B1: Nombre Local
A2: 0 | B2: Todos los locales
A3: 847 | B3: J868 JUMBO APOQUINDO AV. APOQUINDO 5421 LAS CONDES
A4: 846 | B4: N542 SANTA ISABEL PLAZA VIÑA (L.542 )
A5: 844 | B5: N856 SANTA ISABEL RAHUE LA MISION 2585 OSORNO
A6: 843 | B6: 0910 HIPER LIDER - CAMINO LA FARFANA 1400, MAIPU
A7: 842 | B7: 647 LIDER EXPRESS - RUTA F-30 E LOTE R-1, PUCHUNCAVÍ
A8: 841 | B8: 220 TOTTUS - RUTA F-30-E CON ISIDRO GAETE, PUCHUNCAVÍ
A9: 840 | B9: 0624 UNIMARC - AVDA PRESIDENTE RIOS 672, PUCHUNCAVÍ
A10: 839 | B10: 125 TOTTUS - CENTRAL 12400, CHAMISERO
A11: 838 | B11: 131 TOTTUS - AV. CHICUREO 7100, COLINA PIEDRA ROJA
A12: 837 | B12: 110 TOTTUS - AVDA CONCEPCION 47, COLINA CENTRO
A13: 836 | B13: N857 SANTA ISABEL - CAMINO 2° FAJA AL VOLCÁN #205, LOCAL 8, VILLARRICA
... A723: 1 | B723: CASA MATRIZ GRUPOPROGESTION

Sheet Elementos
A1: Id Elemento | B1: Nombre Elemento | C1: Categoria | D1: Marca | E1: Cod_SKU
A2: 868 | B2: GRANOLA UNDER FIVE CACAO CRUNCH C9 300GR | C2: Categorías Snack Dulce | E2: 930202882
A3: 867 | B3: GRANOLA UNDER FIVE ALMENDRAC9 300GR | C3: Categorías Snack Dulce | E3: 930202881
A4: 866 | B4: CHIPS DE MANZANA FLIP 30X30GR 12M | C4: Categorías Snack Flip | D4: Categorías Snack Flip | E4: 930202738
A5: 865 | B5: CHIPS PAPA BARBECUE FLIP 12X140GR 12M | C5: Categorías Snack Flip | D5: Categorías Snack Flip | E5: 930202696
A6: 864 | B6: CHIPS PAPA MERKEN FLIP 12X140GR 12M | C6: Categorías Snack Flip | D6: Categorías Snack Flip | E6: 930202687
A7: 863 | B7: CHIPS PAPA AJO/ALBAHACA 12X140GR 12M | C7: Categorías Snack Flip | D7: Categorías Snack Flip | E7: 930202686
A8: 862 | B8: CHIPS PAPA SAL DE MAR FLIP 12X140GR 12M | C8: Categorías Snack Flip | D8: Categorías Snack Flip | E8: 930202685
A9: 861 | B9: BALLS UF COFFEE C50 60GR | C9: Tradicional | D9: Carteleria | E9: 930202716
A10: 860 | B10: BALLS UF COCO C50 60GR | C10: Tradicional | D10: Carteleria | E10: 930202715
A11: 859 | B11: BALLS UF CACAO C50 60GR | C11: Tradicional | D11: Carteleria | E11: 930202714
A12: 858 | B12: BALLS UF ALMENDRA/CRUNCH C50 60GR | C12: Tradicional | D12: Carteleria | E12: 930202713
A13: 857 | B13: ALMEJA AL NATURAL 180 GRS SAN JOSÉ 180 GRS | C13: Tradicional | D13: Carteleria | E13: 930101655
A14: 856 | B14: LATA ATOM FRUIT LIMÓN MENT JENG 12X250ML | C14: Tradicional | D14: Carteleria | E14: 930202723
A15: 855 | B15: LATA ATOM FRUIT MANGO 12X250ML | C15: Tradicional | D15: Carteleria | E15: 930202722
... A33: 837 | B33: BARRA UF CACAO/MANÍ D5 C20 225GR | C33: Tradicional | D33: Carteleria | E33: 930202703
A34: 836 | B34: ISLA-ATÚN LOMOS SJ ( NAT-ACEITE) | C34: AC
A35: 835 | B35: CABECERAS-ATÚN LOMOS SJ ( NAT-ACEITE) | C35: AC
A36: 834 | B36: CHIPS FLIP NATIVAS 12X140GRS 12M | C36: FLIP | D36: FLIP | E36: 930202672
A37: 833 | B37: PACK COLACIÓN FLIP 5UNI 30GRS | C37: FLIP | D37: FLIP | E37: 930202666
A38: 832 | B38: PAYLOADER-ATÚN LOMOS SJ ( NAT-ACEITE) | C38: AC
A39: 831 | B39: ISLA/CABECERA-JUREL ED LIMITADA NAT SJ 24X425 260GR. | C39: AC
A40: 830 | B40: CHIPS MIX CAM/ZAN/MANZ FLIP 12X140GR 12M | C40: FLIP | D40: FLIP | E40: 930202692
A41: 829 | B41: CHIPS MIX MANZ ROJA/MANZ VERDE 140GR 12M | C41: FLIP | D41: FLIP | E41: 930202693
A42: 828 | B42: CHIPS MIX PAPA/CAM/ZAN/BETA 12X140GR 12_M | C42: FLIP | D42: FLIP | E42: 930202684
A43: 827 | B43: CHIPS MIX CAM/BETA FLIP 12X140GR 12M | C43: FLIP | D43: FLIP | E43: 930202691
A44: 826 | B44: CABECERA|JUREL NAT.SAN JOSE TALL EASYOPEN NAC. | C44: AC
A45: 825 | B45: ISLA|JUREL NAT.SAN JOSE TALL EASYOPEN NAC. | C45: AC
A46: 824 | B46: ISLA|JUREL NATURAL IN&OUT SJ | C46: AC
A47: 823 | B47: CABECERA|JUREL NATURAL IN&OUT SJ | C47: AC
A48: 822 | B48: CABECERA MIXTA|JUREL NATURAL IN&OUT SJ | C48: AC
A49: 821 | B49: ISLA|LOMOS DE JUREL SJ | C49: AC
A50: 820 | B50: MERLUZA FILETE CONG ONICE SJ 10X500 | C50: SAN JOSÉ | D50: SAN JOSÉ | E50: 930202958
A51: 819 | B51: CHIPS PAPA SAL DE MAR FLIP 12X140GR | C51: FLIP | D51: FLIP | E51: 930202184
A52: 818 | B52: CHIPS MIX PAPA/CAM/ZAN/BET FLIP 30 GR | C52: FLIP | D52: FLIP | E52: 930202214
A53: 817 | B53: CHIPS PAPA MERKEN FLIP 30 GR | C53: FLIP | D53: FLIP | E53: 930202213
A54: 816 | B54: CHIPS PAPA SAL DE MAR FLIP 30 GR | C54: FLIP | D54: FLIP | E54: 930202212
A55: 815 | B55: CHIPS MIX PAPA/CAMOTE/ZANAHORIA/BETARRAG | C55: FLIP | D55: FLIP | E55: 930202187
A56: 814 | B56: ATUN LOM ACT SJ 48X160 | C56: SAN JOSÉ | D56: SAN JOSÉ | E56: 930200637
A57: 813 | B57: ATUN LOM NAT SJ 48X160 | C57: SAN JOSÉ | D57: SAN JOSÉ | E57: 930200636
...
